package ch26_Exceptions;

import java.util.Scanner;

public class C01_ArithmeticException {

    //ArithmeticException -> Matematiksel işlemlerde oluşan RTE Exception'dır

    public static void main(String[] args) {

        Scanner input = new Scanner(System.in);

        System.out.println("1. sayi gir");
        int sayi1 = input.nextInt();

        System.out.println("2. sayi gir");
        int sayi2 = input.nextInt();

        //RTE     int sonuc = sayi1 / sayi2 ;
        //Exception in thread "main" java.lang.ArithmeticException: / by zero

        System.out.println("uygulama calismaya devam ediyor");

        try {//kodu ilk derleyen block burasidir
              /*
            1- try-catch kullanıldıgında try block hatasız çalışırsa catch block asla çalışmaz catch block, try
            block exception  yakalarsa calışır
            2- try block catch veya finally block olmadan CTE verir. try block'tan sonra birden fazla catch
            block tanımlanabilir.
               aynıa anda  sadece bir catch block çalışabilir hiç bir catch block çalışmaya da bilir
            3- parent - child ilişkisi olan catch'lerde child önce yazılmalı aksi halde CTE
             */

            int sonuc = sayi1 / sayi2 ;
            System.out.println("sonuc = " + sonuc);
            System.out.println("try block icerisinden geliyor");
        } catch (StringIndexOutOfBoundsException ex) {
            System.out.println("StringIndexOutOfBoundsException sayi sifira bolunmez");
            System.out.println("ex.getMessage() = " + ex.getMessage());

        }catch (ArithmeticException e) {//birden catch de asagiya dogru class level artarak yazilmali
            System.out.println("ArithmeticException sayi sifira baolunmez");


        }catch (Exception e) {
            System.out.println("Exception eger bir exception varsa yukardakiler disinda caliscak yer burasi");

        }


        finally {
            System.out.println("finally blocktan selamlar her zman calisiri");
             /*
            try - catch içinde yapılna işlemlerden sonra mutlaka çalışması gerekn block vatsa finally tanımlanır.
            ama finaly tanımlanırsa catch çalışmasa bile
            pr akışı devam eder.finally block hata olsa da olmasa da calışır.
            Cloud database ortamlarında bağlantı kesmek için kullanılır.cloud ile connection yazdıgınızda code
            başarılı bir şekilde çalışırsa işlem bitiiğinde finally block ile connection kapanmazsa maliyet pahalı olur :(
             */
        }
        System.out.println("class in en son kodu bakalim konsolda gorcez mi?");

    }

}
